<?xml version="1.0"?>
<robot xmlns:xacro="http://ros.org/wiki/xacro">

  <!-- =============== 夹爪基座（固定在 Link6 上） =============== -->
  <link name="gripper_base">
    <visual>
      <geometry><box size="0.05 0.05 0.05"/></geometry>
      <material name="grey"><color rgba="0.5 0.5 0.5 1"/></material>
    </visual>
    <collision>
      <geometry><box size="0.05 0.05 0.05"/></geometry>
    </collision>
    <inertial>
      <mass value="0.1"/>
      <inertia ixx="0.001" ixy="0" ixz="0" iyy="0.001" iyz="0" izz="0.001"/>
    </inertial>
  </link>

  <joint name="gripper_base_joint" type="fixed">
    <parent link="Link6"/>
    <child link="gripper_base"/>
    <origin xyz="0 0 -0.02" rpy="0 0 0"/>
  </joint>

  <!-- =============== 左手指（钩子向内突出） =============== -->
  <link name="gripper_left">
    <!-- 手指主体 -->
    <visual>
      <geometry><box size="0.01 0.05 0.06"/></geometry>
      <material name="grey"><color rgba="0.5 0.5 0.5 1"/></material>
    </visual>
    <collision>
      <geometry><box size="0.01 0.05 0.06"/></geometry>
    </collision>

    <!-- 钩子：位于手指末端（z 负方向，靠近物体），向内（-x 方向）突出 -->
    <!-- 注意：左手指的 x 正方向是向外侧，闭合时向 -x 移动，因此钩子应伸向 -x -->
    <visual name="left_hook_visual">
      <origin xyz="-0.008 0.00 0.03" rpy="0 0 0"/>
      <geometry><box size="0.025 0.05 0.01"/></geometry>
      <material name="grey"><color rgba="0.5 0.5 0.5 1"/></material>
    </visual>
    <collision name="left_hook_collision">
      <origin xyz="-0.008 0.00 0.03" rpy="0 0 0"/>
      <geometry><box size="0.025 0.05 0.01"/></geometry>
    </collision>

    <inertial>
      <mass value="0.06"/>
      <inertia ixx="0.01" ixy="0" ixz="0" iyy="0.01" iyz="0" izz="0.01"/>
    </inertial>
  </link>

  <joint name="gripper_left_joint" type="prismatic">
    <parent link="gripper_base"/>
    <child link="gripper_left"/>
    <origin xyz="0.02 0 0.05" rpy="0 0 0"/>
    <axis xyz="1 0 0"/>
    <limit lower="0" upper="0.04" effort="100" velocity="0.02"/>
  </joint>

  <!-- =============== 右手指（钩子向内突出） =============== -->
  <link name="gripper_right">
    <visual>
      <geometry><box size="0.01 0.05 0.06"/></geometry>
      <material name="grey"><color rgba="0.5 0.5 0.5 1"/></material>
    </visual>
    <collision>
      <geometry><box size="0.01 0.05 0.06"/></geometry>
    </collision>

    <!-- 右手指的钩子：向内（+x 方向）突出 -->
    <visual name="right_hook_visual">
      <origin xyz="0.008 0.00 0.03" rpy="0 0 0"/>
      <geometry><box size="0.025 0.05 0.01"/></geometry>
      <material name="grey"><color rgba="0.5 0.5 0.5 1"/></material>
    </visual>
    <collision name="right_hook_collision">
      <origin xyz="0.008 0.00 0.03" rpy="0 0 0"/>
      <geometry><box size="0.025 0.05 0.01"/></geometry>
    </collision>

    <inertial>
      <mass value="0.06"/>
      <inertia ixx="0.01" ixy="0" ixz="0" iyy="0.01" iyz="0" izz="0.01"/>
    </inertial>
  </link>

  <joint name="gripper_right_joint" type="prismatic">
    <parent link="gripper_base"/>
    <child link="gripper_right"/>
    <origin xyz="-0.02 0 0.05" rpy="0 0 0"/>
    <axis xyz="-1 0 0"/>
    <limit lower="0" upper="0.04" effort="100" velocity="0.02"/>
  </joint>

  <!-- =============== 传动（力矩控制接口） =============== -->
  <transmission name="gripper_left_trans">
    <type>transmission_interface/SimpleTransmission</type>
    <joint name="gripper_left_joint">
      <hardwareInterface>hardware_interface/EffortJointInterface</hardwareInterface>
    </joint>
    <actuator name="gripper_left_motor">
      <mechanicalReduction>1</mechanicalReduction>
    </actuator>
  </transmission>

  <transmission name="gripper_right_trans">
    <type>transmission_interface/SimpleTransmission</type>
    <joint name="gripper_right_joint">
      <hardwareInterface>hardware_interface/EffortJointInterface</hardwareInterface>
    </joint>
    <actuator name="gripper_right_motor">
      <mechanicalReduction>1</mechanicalReduction>
    </actuator>
  </transmission>

  <!-- Gazebo 摩擦/接触参数 -->
  <gazebo reference="gripper_left">
    <mu1>100.0</mu1>
    <mu2>100.0</mu2>
    <kp>100000000.0</kp>
    <kd>100.0</kd>
    <minDepth>0.005</minDepth>
    <maxVel>0.0</maxVel>
  </gazebo>

  <gazebo reference="gripper_right">
    <mu1>100.0</mu1>
    <mu2>100.0</mu2>
    <kp>100000000.0</kp>
    <kd>100.0</kd>
    <minDepth>0.005</minDepth>
    <maxVel>0.0</maxVel>
  </gazebo>

</robot>
